<?xml version="1.0"?>
<robot name="maze_bot">

    <material name="gray">
        <color rgba=".2 0.2 0.2 1.0" />
    </material>
    <material name="white">
        <color rgba="1.0 1.0 0.8 1.0" />
    </material>

    <link name="base_footprint" />

    <link name="base">
        <visual>
            <geometry>
                <box size="0.75 0.4 0.1" />
            </geometry>
            <material name="gray" />
        </visual>

        <collision>
            <geometry>
                <box size="0.75 0.4 0.1" />
            </geometry>
            <contact_coefficients mu="0" kp="1000.0" kd="1.0" />
        </collision>
    </link>

    <joint name="base_joint" type="fixed">
        <parent link="base_footprint" />
        <child link="base" />
        <origin xyz="0.0 0.0 0.0" rpy="0.0 0.0 0.135" />
    </joint>

    <link name="right_wheel">
        <inertial>
            <mass value="1" />
            <inertia ixx="100" ixy="0" ixz="100" iyy="100" iyz="0" izz="100" />
        </inertial>

        <visual>
            <geometry>
                <cylinder radius="0.15" length="0.06" />
                <material name="white" />
            </geometry>
        </visual>

        <collision>
            <geometry>
                <cylinder radius="0.15" length="0.06" />
            </geometry>
            <contact_coefficients mu="0" kp="1000.0" kd="1.0" />
        </collision>
    </link>

    <joint name="wheel_right_joint" type="continuous">
        <origin xyz="0.2 0.25 0.0" rpy="1.57 0.0 0.0" />
        <parent link="base" />
        <child link="right_wheel" />
        <axis xyz="0.0 0.0 1.0" />
    </joint>

    <link name="left_wheel">
        <inertial>
            <mass value="1" />
            <inertia ixx="100" ixy="0" ixz="100" iyy="100" iyz="0" izz="100" />
        </inertial>

        <visual>
            <geometry>
                <cylinder radius="0.15" length="0.06" />
                <material name="white" />
            </geometry>
        </visual>

        <collision>
            <geometry>
                <cylinder radius="0.15" length="0.06" />
            </geometry>
            <contact_coefficients mu="0" kp="1000.0" kd="1.0" />
        </collision>
    </link>

    <joint name="wheel_left_joint" type="continuous">
        <origin xyz="0.2 -0.25 0.0" rpy="1.57 0.0 0.0" />
        <parent link="base" />
        <child link="left_wheel" />
        <axis xyz="0.0 0.0 1.0" />
    </joint>

    <link name="caster">
        <inertial>
            <mass value="1" />
            <inertia ixx="100" ixy="0" ixz="100" iyy="100" iyz="0" izz="100" />
        </inertial>

        <visual>
            <geometry>
                <sphere radius="0.08" />
                <material name="white"/>
            </geometry>
        </visual>

        <collision>
            <origin xyz="0.0 0.0 0.0" rpy="0.0 0.0 0.0"/>
            <geometry>
                <sphere radius="0.08" />
            </geometry>
            <contact_coefficients mu="0" kp="1000.0" kd="1.0" />
        </collision>
    </link>

    <joint name="caster_joint" type="continuous">
        <origin xyz="-0.3 0.0 -0.07" rpy="0.0 0.0 0.0"/>
        <parent link="base"/>
        <child link="caster"/>
        <axis xyz="0.0 0.0 1.0"/>
    </joint>
    
</robot>